{
	"registryname":"stabilizer",
	"localizedname":"稳定器",
	"requires-blueprint":true,
	"color":"CC400F",
    "parts": [
        {
            "x": 6,
            "y": -7,
            "z": 6,
            "elements": [
                "environmentaltech:structure_frame_5@0"
            ]
        },
        {
            "x": 0,
            "y": -11,
            "z": -1,
            "elements": [
                "draconicevolution:draconic_block@0"
            ]
        },
        {
            "x": -2,
            "y": -15,
            "z": -16,
            "elements": [
                "contenttweaker:psogereer_rock@0"
            ]
        },
        {
            "x": -3,
            "y": -5,
            "z": 6,
            "elements": [
                "enderio:block_alloy@8"
            ]
        },
        {
            "x": -7,
            "y": -7,
            "z": -4,
            "elements": [
                "environmentaltech:structure_frame_5@0"
            ]
        },
        {
            "x": 0,
            "y": -11,
            "z": 10,
            "elements": [
                "draconicevolution:draconic_block@0"
            ]
        },
        {
            "x": 5,
            "y": -11,
            "z": 0,
            "elements": [
                "draconicevolution:draconic_block@0"
            ]
        },
        {
            "x": 1,
            "y": -9,
            "z": 10,
            "elements": [
                "botania:storage@1"
            ]
        },
        {
            "x": 5,
            "y": -13,
            "z": -14,
            "elements": [
                "thaumcraft:metal_thaumium@0"
            ]
        },
        {
            "x": -3,
            "y": -7,
            "z": -8,
            "elements": [
                "environmentaltech:structure_frame_5@0"
            ]
        },
        {
            "x": 0,
            "y": -15,
            "z": 7,
            "elements": [
                "draconicevolution:draconic_block@0"
            ]
        },
        {
            "x": -8,
            "y": -11,
            "z": 9,
            "elements": [
                "contenttweaker:sub_block_holder_5@0"
            ]
        },
        {
            "x": 8,
            "y": -15,
            "z": 0,
            "elements": [
                "draconicevolution:draconic_block@0"
            ]
        },
        {
            "x": 1,
            "y": -3,
            "z": 0,
            "elements": [
                "draconicevolution:draconic_block@0"
            ]
        },
        {
            "x": 15,
            "y": -15,
            "z": 6,
            "elements": [
                "contenttweaker:psogereer_rock@0"
            ]
        },
        {
            "x": -8,
            "y": -13,
            "z": -12,
            "elements": [
                "thaumcraft:metal_thaumium@0"
            ]
        },
        {
            "x": 3,
            "y": -7,
            "z": 0,
            "elements": [
                "draconicevolution:draconic_block@0"
            ]
        },
        {
            "x": 2,
            "y": -7,
            "z": 0,
            "elements": [
                "draconicevolution:draconic_block@0"
            ]
        },
        {
            "x": 12,
            "y": -13,
            "z": 8,
            "elements": [
                "thaumcraft:metal_thaumium@0"
            ]
        },
        {
            "x": -8,
            "y": -7,
            "z": -2,
            "elements": [
                "environmentaltech:structure_frame_5@0"
            ]
        },
        {
            "x": 0,
            "y": -5,
            "z": 6,
            "elements": [
                "enderio:block_alloy@8"
            ]
        },
        {
            "x": 10,
            "y": -15,
            "z": -13,
            "elements": [
                "contenttweaker:psogereer_rock@0"
            ]
        },
        {
            "x": 9,
            "y": -11,
            "z": 9,
            "elements": [
                "contenttweaker:sub_block_holder_5@0"
            ]
        },
        {
            "x": 8,
            "y": -7,
            "z": 1,
            "elements": [
                "environmentaltech:structure_frame_5@0"
            ]
        },
        {
            "x": 0,
            "y": -15,
            "z": 3,
            "elements": [
                "draconicevolution:draconic_block@0"
            ]
        },
        {
            "x": 4,
            "y": -11,
            "z": 0,
            "elements": [
                "draconicevolution:draconic_block@0"
            ]
        },
        {
            "x": 0,
            "y": -9,
            "z": 10,
            "elements": [
                "botania:storage@1"
            ]
        },
        {
            "x": 4,
            "y": -13,
            "z": -14,
            "elements": [
                "thaumcraft:metal_thaumium@0"
            ]
        },
        {
            "x": 4,
            "y": -5,
            "z": -5,
            "elements": [
                "enderio:block_alloy@8"
            ]
        },
        {
            "x": -10,
            "y": -11,
            "z": -7,
            "elements": [
                "contenttweaker:sub_block_holder_5@0"
            ]
        },
        {
            "x": 5,
            "y": -11,
            "z": 11,
            "elements": [
                "contenttweaker:sub_block_holder_5@0"
            ]
        },
        {
            "x": -2,
            "y": -11,
            "z": -12,
            "elements": [
                "contenttweaker:sub_block_holder_5@0"
            ]
        },
        {
            "x": 4,
            "y": -11,
            "z": 12,
            "elements": [
                "contenttweaker:sub_block_holder_5@0"
            ]
        },
        {
            "x": 9,
            "y": -15,
            "z": 14,
            "elements": [
                "contenttweaker:psogereer_rock@0"
            ]
        },
        {
            "x": 10,
            "y": -13,
            "z": -10,
            "elements": [
                "thaumcraft:metal_thaumium@0"
            ]
        },
        {
            "x": 0,
            "y": -15,
            "z": 4,
            "elements": [
                "draconicevolution:draconic_block@0"
            ]
        },
        {
            "x": 8,
            "y": -7,
            "z": -1,
            "elements": [
                "environmentaltech:structure_frame_5@0"
            ]
        },
        {
            "x": 7,
            "y": -15,
            "z": 0,
            "elements": [
                "draconicevolution:draconic_block@0"
            ]
        },
        {
            "x": 0,
            "y": -3,
            "z": 0,
            "elements": [
                "modularmachinery:blockinputbus@0"
            ]
        },
        {
            "x": 1,
            "y": -15,
            "z": -16,
            "elements": [
                "contenttweaker:psogereer_rock@0"
            ]
        },
        {
            "x": 10,
            "y": -13,
            "z": -11,
            "elements": [
                "thaumcraft:metal_thaumium@0"
            ]
        },
        {
            "x": -13,
            "y": -13,
            "z": -6,
            "elements": [
                "thaumcraft:metal_thaumium@0"
            ]
        },
        {
            "x": 7,
            "y": -13,
            "z": -13,
            "elements": [
                "thaumcraft:metal_thaumium@0"
            ]
        },
        {
            "x": -14,
            "y": -13,
            "z": 2,
            "elements": [
                "thaumcraft:metal_thaumium@0"
            ]
        },
        {
            "x": -4,
            "y": -7,
            "z": -7,
            "elements": [
                "environmentaltech:structure_frame_5@0"
            ]
        },
        {
            "x": -8,
            "y": -15,
            "z": 14,
            "elements": [
                "contenttweaker:psogereer_rock@0"
            ]
        },
        {
            "x": 1,
            "y": -7,
            "z": 0,
            "elements": [
                "draconicevolution:draconic_block@0"
            ]
        },
        {
            "x": 7,
            "y": -11,
            "z": 0,
            "elements": [
                "draconicevolution:draconic_block@0"
            ]
        },
        {
            "x": -6,
            "y": -9,
            "z": -8,
            "elements": [
                "botania:storage@1"
            ]
        },
        {
            "x": -8,
            "y": -7,
            "z": 2,
            "elements": [
                "environmentaltech:structure_frame_5@0"
            ]
        },
        {
            "x": -2,
            "y": -15,
            "z": 16,
            "elements": [
                "contenttweaker:psogereer_rock@0"
            ]
        },
        {
            "x": 14,
            "y": -13,
            "z": 1,
            "elements": [
                "thaumcraft:metal_thaumium@0"
            ]
        },
        {
            "x": 3,
            "y": -5,
            "z": 6,
            "elements": [
                "enderio:block_alloy@8"
            ]
        },
        {
            "x": -1,
            "y": -9,
            "z": 10,
            "elements": [
                "botania:storage@1"
            ]
        },
        {
            "x": 0,
            "y": -15,
            "z": -8,
            "elements": [
                "draconicevolution:draconic_block@0"
            ]
        },
        {
            "x": 0,
            "y": -15,
            "z": -1,
            "elements": [
                "draconicevolution:draconic_block@0"
            ]
        },
        {
            "x": -16,
            "y": -15,
            "z": 1,
            "elements": [
                "contenttweaker:psogereer_rock@0"
            ]
        },
        {
            "x": -10,
            "y": -11,
            "z": -8,
            "elements": [
                "contenttweaker:sub_block_holder_5@0"
            ]
        },
        {
            "x": -2,
            "y": -1,
            "z": 0,
            "elements": [
                "libvulpes:advstructuremachine@0"
            ]
        },
        {
            "x": 3,
            "y": -3,
            "z": 0,
            "elements": [
                "draconicevolution:draconic_block@0"
            ]
        },
        {
            "x": 14,
            "y": -13,
            "z": -1,
            "elements": [
                "thaumcraft:metal_thaumium@0"
            ]
        },
        {
            "x": 1,
            "y": -11,
            "z": 12,
            "elements": [
                "contenttweaker:sub_block_holder_5@0"
            ]
        },
        {
            "x": 13,
            "y": -13,
            "z": -6,
            "elements": [
                "thaumcraft:metal_thaumium@0"
            ]
        },
        {
            "x": 0,
            "y": -15,
            "z": -4,
            "elements": [
                "draconicevolution:draconic_block@0"
            ]
        },
        {
            "x": 14,
            "y": -13,
            "z": 2,
            "elements": [
                "thaumcraft:metal_thaumium@0"
            ]
        },
        {
            "x": 0,
            "y": -15,
            "z": 10,
            "elements": [
                "draconicevolution:draconic_block@0"
            ]
        },
        {
            "x": -6,
            "y": -5,
            "z": -1,
            "elements": [
                "enderio:block_alloy@8"
            ]
        },
        {
            "x": -5,
            "y": -9,
            "z": 9,
            "elements": [
                "botania:storage@1"
            ]
        },
        {
            "x": 4,
            "y": -15,
            "z": -16,
            "elements": [
                "contenttweaker:psogereer_rock@0"
            ]
        },
        {
            "x": -5,
            "y": -15,
            "z": -16,
            "elements": [
                "contenttweaker:psogereer_rock@0"
            ]
        },
        {
            "x": 0,
            "y": -11,
            "z": 3,
            "elements": [
                "draconicevolution:draconic_block@0"
            ]
        },
        {
            "x": -7,
            "y": -7,
            "z": 4,
            "elements": [
                "environmentaltech:structure_frame_5@0"
            ]
        },
        {
            "x": 0,
            "y": -7,
            "z": 5,
            "elements": [
                "draconicevolution:draconic_block@0"
            ]
        },
        {
            "x": 2,
            "y": -9,
            "z": 10,
            "elements": [
                "botania:storage@1"
            ]
        },
        {
            "x": 2,
            "y": -13,
            "z": -14,
            "elements": [
                "thaumcraft:metal_thaumium@0"
            ]
        },
        {
            "x": 6,
            "y": -9,
            "z": 9,
            "elements": [
                "botania:storage@1"
            ]
        },
        {
            "x": 2,
            "y": -11,
            "z": 0,
            "elements": [
                "draconicevolution:draconic_block@0"
            ]
        },
        {
            "x": 5,
            "y": -15,
            "z": 0,
            "elements": [
                "draconicevolution:draconic_block@0"
            ]
        },
        {
            "x": 0,
            "y": -11,
            "z": 6,
            "elements": [
                "draconicevolution:draconic_block@0"
            ]
        },
        {
            "x": 7,
            "y": -11,
            "z": -10,
            "elements": [
                "contenttweaker:sub_block_holder_5@0"
            ]
        },
        {
            "x": 13,
            "y": -15,
            "z": -10,
            "elements": [
                "contenttweaker:psogereer_rock@0"
            ]
        },
        {
            "x": 4,
            "y": -15,
            "z": 16,
            "elements": [
                "contenttweaker:psogereer_rock@0"
            ]
        },
        {
            "x": -2,
            "y": -3,
            "z": 0,
            "elements": [
                "draconicevolution:draconic_block@0"
            ]
        },
        {
            "x": -2,
            "y": -11,
            "z": 12,
            "elements": [
                "contenttweaker:sub_block_holder_5@0"
            ]
        },
        {
            "x": 12,
            "y": -11,
            "z": -1,
            "elements": [
                "contenttweaker:sub_block_holder_5@0"
            ]
        },
        {
            "x": 4,
            "y": -7,
            "z": 0,
            "elements": [
                "draconicevolution:draconic_block@0"
            ]
        },
        {
            "x": -10,
            "y": -11,
            "z": 8,
            "elements": [
                "contenttweaker:sub_block_holder_5@0"
            ]
        },
        {
            "x": 0,
            "y": -7,
            "z": -5,
            "elements": [
                "draconicevolution:draconic_block@0"
            ]
        },
        {
            "x": 14,
            "y": -13,
            "z": -4,
            "elements": [
                "thaumcraft:metal_thaumium@0"
            ]
        },
        {
            "x": 9,
            "y": -11,
            "z": 0,
            "elements": [
                "draconicevolution:draconic_block@0"
            ]
        },
        {
            "x": -2,
            "y": -5,
            "z": -6,
            "elements": [
                "enderio:block_alloy@8"
            ]
        },
        {
            "x": -11,
            "y": -15,
            "z": -12,
            "elements": [
                "contenttweaker:psogereer_rock@0"
            ]
        },
        {
            "x": 9,
            "y": -9,
            "z": -5,
            "elements": [
                "botania:storage@1"
            ]
        },
        {
            "x": -12,
            "y": -11,
            "z": -1,
            "elements": [
                "contenttweaker:sub_block_holder_5@0"
            ]
        },
        {
            "x": -5,
            "y": -9,
            "z": -9,
            "elements": [
                "botania:storage@1"
            ]
        },
        {
            "x": 8,
            "y": -9,
            "z": 7,
            "elements": [
                "botania:storage@1"
            ]
        },
        {
            "x": 5,
            "y": -5,
            "z": 4,
            "elements": [
                "enderio:block_alloy@8"
            ]
        },
        {
            "x": 3,
            "y": -13,
            "z": 14,
            "elements": [
                "thaumcraft:metal_thaumium@0"
            ]
        },
        {
            "x": 8,
            "y": -7,
            "z": 3,
            "elements": [
                "environmentaltech:structure_frame_5@0"
            ]
        },
        {
            "x": 2,
            "y": -3,
            "z": 4,
            "elements": [
                "modularmachinery:blockcasing@4"
            ]
        },
        {
            "x": 4,
            "y": -9,
            "z": 10,
            "elements": [
                "botania:storage@1"
            ]
        },
        {
            "x": 6,
            "y": -5,
            "z": 0,
            "elements": [
                "enderio:block_alloy@8"
            ]
        },
        {
            "x": -7,
            "y": -9,
            "z": -8,
            "elements": [
                "botania:storage@1"
            ]
        },
        {
            "x": -10,
            "y": -9,
            "z": -2,
            "elements": [
                "botania:storage@1"
            ]
        },
        {
            "x": 8,
            "y": -7,
            "z": 4,
            "elements": [
                "environmentaltech:structure_frame_5@0"
            ]
        },
        {
            "x": -3,
            "y": -3,
            "z": 0,
            "elements": [
                "draconicevolution:draconic_block@0"
            ]
        },
        {
            "x": -1,
            "y": -3,
            "z": -4,
            "elements": [
                "modularmachinery:blockcasing@4"
            ]
        },
        {
            "x": 7,
            "y": -7,
            "z": 0,
            "elements": [
                "draconicevolution:draconic_block@0"
            ]
        },
        {
            "x": 14,
            "y": -13,
            "z": -3,
            "elements": [
                "thaumcraft:metal_thaumium@0"
            ]
        },
        {
            "x": 6,
            "y": -13,
            "z": 13,
            "elements": [
                "thaumcraft:metal_thaumium@0"
            ]
        },
        {
            "x": 9,
            "y": -13,
            "z": -11,
            "elements": [
                "thaumcraft:metal_thaumium@0"
            ]
        },
        {
            "x": -14,
            "y": -15,
            "z": 8,
            "elements": [
                "contenttweaker:psogereer_rock@0"
            ]
        },
        {
            "x": -12,
            "y": -11,
            "z": 2,
            "elements": [
                "contenttweaker:sub_block_holder_5@0"
            ]
        },
        {
            "x": -8,
            "y": -13,
            "z": 12,
            "elements": [
                "thaumcraft:metal_thaumium@0"
            ]
        },
        {
            "x": 14,
            "y": -13,
            "z": 4,
            "elements": [
                "thaumcraft:metal_thaumium@0"
            ]
        },
        {
            "x": -5,
            "y": -15,
            "z": 16,
            "elements": [
                "contenttweaker:psogereer_rock@0"
            ]
        },
        {
            "x": 0,
            "y": -11,
            "z": 0,
            "elements": [
                "modularmachinery:blockoutputbus"
            ]
        },
        {
            "x": 0,
            "y": -15,
            "z": 6,
            "elements": [
                "draconicevolution:draconic_block@0"
            ]
        },
        {
            "x": -9,
            "y": -11,
            "z": -8,
            "elements": [
                "contenttweaker:sub_block_holder_5@0"
            ]
        },
        {
            "x": 3,
            "y": -15,
            "z": 0,
            "elements": [
                "draconicevolution:draconic_block@0"
            ]
        },
        {
            "x": 4,
            "y": -3,
            "z": 0,
            "elements": [
                "modularmachinery:blockcasing@4"
            ]
        },
        {
            "x": -9,
            "y": -9,
            "z": 6,
            "elements": [
                "botania:storage@1"
            ]
        },
        {
            "x": -10,
            "y": -15,
            "z": -13,
            "elements": [
                "contenttweaker:psogereer_rock@0"
            ]
        },
        {
            "x": 14,
            "y": -13,
            "z": 3,
            "elements": [
                "thaumcraft:metal_thaumium@0"
            ]
        },
        {
            "x": 5,
            "y": -5,
            "z": -4,
            "elements": [
                "enderio:block_alloy@8"
            ]
        },
        {
            "x": 0,
            "y": -11,
            "z": 5,
            "elements": [
                "draconicevolution:draconic_block@0"
            ]
        },
        {
            "x": 7,
            "y": -15,
            "z": -15,
            "elements": [
                "contenttweaker:psogereer_rock@0"
            ]
        },
        {
            "x": -6,
            "y": -5,
            "z": 3,
            "elements": [
                "enderio:block_alloy@8"
            ]
        },
        {
            "x": 6,
            "y": -7,
            "z": 0,
            "elements": [
                "draconicevolution:draconic_block@0"
            ]
        },
        {
            "x": 9,
            "y": -9,
            "z": 6,
            "elements": [
                "botania:storage@1"
            ]
        },
        {
            "x": -3,
            "y": -7,
            "z": 0,
            "elements": [
                "draconicevolution:draconic_block@0"
            ]
        },
        {
            "x": 3,
            "y": -11,
            "z": 0,
            "elements": [
                "draconicevolution:draconic_block@0"
            ]
        },
        {
            "x": 7,
            "y": -7,
            "z": 5,
            "elements": [
                "environmentaltech:structure_frame_5@0"
            ]
        },
        {
            "x": 4,
            "y": -11,
            "z": -12,
            "elements": [
                "contenttweaker:sub_block_holder_5@0"
            ]
        },
        {
            "x": 11,
            "y": -13,
            "z": -10,
            "elements": [
                "thaumcraft:metal_thaumium@0"
            ]
        },
        {
            "x": 12,
            "y": -15,
            "z": -11,
            "elements": [
                "contenttweaker:psogereer_rock@0"
            ]
        },
        {
            "x": 8,
            "y": -11,
            "z": -10,
            "elements": [
                "contenttweaker:sub_block_holder_5@0"
            ]
        },
        {
            "x": 1,
            "y": -11,
            "z": -12,
            "elements": [
                "contenttweaker:sub_block_holder_5@0"
            ]
        },
        {
            "x": 6,
            "y": -15,
            "z": 0,
            "elements": [
                "draconicevolution:draconic_block@0"
            ]
        },
        {
            "x": -12,
            "y": -13,
            "z": 8,
            "elements": [
                "thaumcraft:metal_thaumium@0"
            ]
        },
        {
            "x": 12,
            "y": -11,
            "z": 3,
            "elements": [
                "contenttweaker:sub_block_holder_5@0"
            ]
        },
        {
            "x": -16,
            "y": -15,
            "z": -3,
            "elements": [
                "contenttweaker:psogereer_rock@0"
            ]
        },
        {
            "x": -15,
            "y": -15,
            "z": -7,
            "elements": [
                "contenttweaker:psogereer_rock@0"
            ]
        },
        {
            "x": 0,
            "y": -7,
            "z": 0,
            "elements": [
                "modularmachinery:blockfluidinputhatch"
            ]
        },
        {
            "x": 16,
            "y": -15,
            "z": -3,
            "elements": [
                "contenttweaker:psogereer_rock@0"
            ]
        },
        {
            "x": 10,
            "y": -15,
            "z": 13,
            "elements": [
                "contenttweaker:psogereer_rock@0"
            ]
        },
        {
            "x": -13,
            "y": -13,
            "z": -7,
            "elements": [
                "thaumcraft:metal_thaumium@0"
            ]
        },
        {
            "x": -14,
            "y": -15,
            "z": 9,
            "elements": [
                "contenttweaker:psogereer_rock@0"
            ]
        },
        {
            "x": 12,
            "y": -15,
            "z": 0,
            "elements": [
                "draconicevolution:draconic_block@0"
            ]
        },
        {
            "x": -2,
            "y": -9,
            "z": 10,
            "elements": [
                "botania:storage@1"
            ]
        },
        {
            "x": -4,
            "y": -3,
            "z": 1,
            "elements": [
                "modularmachinery:blockcasing@4"
            ]
        },
        {
            "x": 6,
            "y": -11,
            "z": 0,
            "elements": [
                "draconicevolution:draconic_block@0"
            ]
        },
        {
            "x": -11,
            "y": -13,
            "z": 9,
            "elements": [
                "thaumcraft:metal_thaumium@0"
            ]
        },
        {
            "x": 0,
            "y": -11,
            "z": 11,
            "elements": [
                "draconicevolution:draconic_block@0"
            ]
        },
        {
            "x": 2,
            "y": -9,
            "z": -10,
            "elements": [
                "botania:storage@1"
            ]
        },
        {
            "x": 4,
            "y": -5,
            "z": 5,
            "elements": [
                "enderio:block_alloy@8"
            ]
        },
        {
            "x": -12,
            "y": -11,
            "z": -2,
            "elements": [
                "contenttweaker:sub_block_holder_5@0"
            ]
        },
        {
            "x": 9,
            "y": -15,
            "z": 0,
            "elements": [
                "draconicevolution:draconic_block@0"
            ]
        },
        {
            "x": 0,
            "y": -15,
            "z": 5,
            "elements": [
                "draconicevolution:draconic_block@0"
            ]
        },
        {
            "x": 8,
            "y": -7,
            "z": -4,
            "elements": [
                "environmentaltech:structure_frame_5@0"
            ]
        },
        {
            "x": -6,
            "y": -7,
            "z": 6,
            "elements": [
                "environmentaltech:structure_frame_5@0"
            ]
        },
        {
            "x": 7,
            "y": -13,
            "z": 13,
            "elements": [
                "thaumcraft:metal_thaumium@0"
            ]
        },
        {
            "x": -7,
            "y": -7,
            "z": 5,
            "elements": [
                "environmentaltech:structure_frame_5@0"
            ]
        },
        {
            "x": 11,
            "y": -11,
            "z": 5,
            "elements": [
                "contenttweaker:sub_block_holder_5@0"
            ]
        },
        {
            "x": -3,
            "y": -13,
            "z": -14,
            "elements": [
                "thaumcraft:metal_thaumium@0"
            ]
        },
        {
            "x": -5,
            "y": -7,
            "z": 0,
            "elements": [
                "draconicevolution:draconic_block@0"
            ]
        },
        {
            "x": 15,
            "y": -15,
            "z": 7,
            "elements": [
                "contenttweaker:psogereer_rock@0"
            ]
        },
        {
            "x": -16,
            "y": -15,
            "z": 0,
            "elements": [
                "contenttweaker:psogereer_rock@0"
            ]
        },
        {
            "x": 15,
            "y": -15,
            "z": 0,
            "elements": [
                "draconicevolution:draconic_block@0"
            ]
        },
        {
            "x": -4,
            "y": -15,
            "z": 16,
            "elements": [
                "contenttweaker:psogereer_rock@0"
            ]
        },
        {
            "x": -2,
            "y": -3,
            "z": 4,
            "elements": [
                "modularmachinery:blockcasing@4"
            ]
        },
        {
            "x": -1,
            "y": -9,
            "z": -10,
            "elements": [
                "botania:storage@1"
            ]
        },
        {
            "x": -2,
            "y": -11,
            "z": 0,
            "elements": [
                "draconicevolution:draconic_block@0"
            ]
        },
        {
            "x": -8,
            "y": -9,
            "z": 6,
            "elements": [
                "botania:storage@1"
            ]
        },
        {
            "x": 9,
            "y": -11,
            "z": -9,
            "elements": [
                "contenttweaker:sub_block_holder_5@0"
            ]
        },
        {
            "x": 6,
            "y": -9,
            "z": -9,
            "elements": [
                "botania:storage@1"
            ]
        },
        {
            "x": -10,
            "y": -11,
            "z": 7,
            "elements": [
                "contenttweaker:sub_block_holder_5@0"
            ]
        },
        {
            "x": 0,
            "y": -11,
            "z": 9,
            "elements": [
                "draconicevolution:draconic_block@0"
            ]
        },
        {
            "x": -8,
            "y": -11,
            "z": 10,
            "elements": [
                "contenttweaker:sub_block_holder_5@0"
            ]
        },
        {
            "x": -10,
            "y": -9,
            "z": 1,
            "elements": [
                "botania:storage@1"
            ]
        },
        {
            "x": 12,
            "y": -11,
            "z": 0,
            "elements": [
                "contenttweaker:sub_block_holder_5@0"
            ]
        },
        {
            "x": -8,
            "y": -9,
            "z": -6,
            "elements": [
                "botania:storage@1"
            ]
        },
        {
            "x": -4,
            "y": -13,
            "z": -14,
            "elements": [
                "thaumcraft:metal_thaumium@0"
            ]
        },
        {
            "x": 0,
            "y": -15,
            "z": 11,
            "elements": [
                "draconicevolution:draconic_block@0"
            ]
        },
        {
            "x": -4,
            "y": -5,
            "z": -5,
            "elements": [
                "enderio:block_alloy@8"
            ]
        },
        {
            "x": 0,
            "y": -15,
            "z": -5,
            "elements": [
                "draconicevolution:draconic_block@0"
            ]
        },
        {
            "x": 6,
            "y": -5,
            "z": 3,
            "elements": [
                "enderio:block_alloy@8"
            ]
        },
        {
            "x": 0,
            "y": -7,
            "z": -2,
            "elements": [
                "draconicevolution:draconic_block@0"
            ]
        },
        {
            "x": -6,
            "y": -11,
            "z": 11,
            "elements": [
                "contenttweaker:sub_block_holder_5@0"
            ]
        },
        {
            "x": -1,
            "y": -15,
            "z": 16,
            "elements": [
                "contenttweaker:psogereer_rock@0"
            ]
        },
        {
            "x": 0,
            "y": -15,
            "z": -7,
            "elements": [
                "draconicevolution:draconic_block@0"
            ]
        },
        {
            "x": 4,
            "y": -3,
            "z": 2,
            "elements": [
                "modularmachinery:blockcasing@4"
            ]
        },
        {
            "x": 7,
            "y": -15,
            "z": 15,
            "elements": [
                "contenttweaker:psogereer_rock@0"
            ]
        },
        {
            "x": 1,
            "y": -3,
            "z": 4,
            "elements": [
                "modularmachinery:blockcasing@4"
            ]
        },
        {
            "x": 2,
            "y": -15,
            "z": 16,
            "elements": [
                "contenttweaker:psogereer_rock@0"
            ]
        },
        {
            "x": 0,
            "y": -3,
            "z": -4,
            "elements": [
                "modularmachinery:blockcasing@4"
            ]
        },
        {
            "x": 6,
            "y": -5,
            "z": -2,
            "elements": [
                "enderio:block_alloy@8"
            ]
        },
        {
            "x": 0,
            "y": -15,
            "z": -12,
            "elements": [
                "draconicevolution:draconic_block@0"
            ]
        },
        {
            "x": -15,
            "y": -15,
            "z": 6,
            "elements": [
                "contenttweaker:psogereer_rock@0"
            ]
        },
        {
            "x": -5,
            "y": -7,
            "z": -7,
            "elements": [
                "environmentaltech:structure_frame_5@0"
            ]
        },
        {
            "x": 14,
            "y": -13,
            "z": 5,
            "elements": [
                "thaumcraft:metal_thaumium@0"
            ]
        },
        {
            "x": -14,
            "y": -15,
            "z": 0,
            "elements": [
                "draconicevolution:draconic_block@0"
            ]
        },
        {
            "x": 14,
            "y": -15,
            "z": 8,
            "elements": [
                "contenttweaker:psogereer_rock@0"
            ]
        },
        {
            "x": 13,
            "y": -15,
            "z": 0,
            "elements": [
                "draconicevolution:draconic_block@0"
            ]
        },
        {
            "x": -1,
            "y": -13,
            "z": -14,
            "elements": [
                "thaumcraft:metal_thaumium@0"
            ]
        },
        {
            "x": -6,
            "y": -5,
            "z": -2,
            "elements": [
                "enderio:block_alloy@8"
            ]
        },
        {
            "x": 11,
            "y": -13,
            "z": -9,
            "elements": [
                "thaumcraft:metal_thaumium@0"
            ]
        },
        {
            "x": 8,
            "y": -11,
            "z": -9,
            "elements": [
                "contenttweaker:sub_block_holder_5@0"
            ]
        },
        {
            "x": 10,
            "y": -9,
            "z": -3,
            "elements": [
                "botania:storage@1"
            ]
        },
        {
            "x": 14,
            "y": -15,
            "z": -9,
            "elements": [
                "contenttweaker:psogereer_rock@0"
            ]
        },
        {
            "x": 1,
            "y": -9,
            "z": -10,
            "elements": [
                "botania:storage@1"
            ]
        },
        {
            "x": 2,
            "y": -7,
            "z": 8,
            "elements": [
                "environmentaltech:structure_frame_5@0"
            ]
        },
        {
            "x": 0,
            "y": -3,
            "z": 4,
            "elements": [
                "modularmachinery:blockcasing@4"
            ]
        },
        {
            "x": -10,
            "y": -15,
            "z": 13,
            "elements": [
                "contenttweaker:psogereer_rock@0"
            ]
        },
        {
            "x": 5,
            "y": -15,
            "z": 16,
            "elements": [
                "contenttweaker:psogereer_rock@0"
            ]
        },
        {
            "x": -3,
            "y": -11,
            "z": -12,
            "elements": [
                "contenttweaker:sub_block_holder_5@0"
            ]
        },
        {
            "x": 1,
            "y": -3,
            "z": -4,
            "elements": [
                "modularmachinery:blockcasing@4"
            ]
        },
        {
            "x": 10,
            "y": -9,
            "z": 0,
            "elements": [
                "botania:storage@1"
            ]
        },
        {
            "x": -9,
            "y": -13,
            "z": 11,
            "elements": [
                "thaumcraft:metal_thaumium@0"
            ]
        },
        {
            "x": -11,
            "y": -11,
            "z": -6,
            "elements": [
                "contenttweaker:sub_block_holder_5@0"
            ]
        },
        {
            "x": -7,
            "y": -15,
            "z": 15,
            "elements": [
                "contenttweaker:psogereer_rock@0"
            ]
        },
        {
            "x": -7,
            "y": -13,
            "z": -13,
            "elements": [
                "thaumcraft:metal_thaumium@0"
            ]
        },
        {
            "x": 14,
            "y": -13,
            "z": -5,
            "elements": [
                "thaumcraft:metal_thaumium@0"
            ]
        },
        {
            "x": -14,
            "y": -13,
            "z": 0,
            "elements": [
                "thaumcraft:metal_thaumium@0"
            ]
        },
        {
            "x": 6,
            "y": -15,
            "z": -15,
            "elements": [
                "contenttweaker:psogereer_rock@0"
            ]
        },
        {
            "x": 11,
            "y": -11,
            "z": -5,
            "elements": [
                "contenttweaker:sub_block_holder_5@0"
            ]
        },
        {
            "x": 10,
            "y": -11,
            "z": 0,
            "elements": [
                "draconicevolution:draconic_block@0"
            ]
        },
        {
            "x": 0,
            "y": -11,
            "z": -2,
            "elements": [
                "draconicevolution:draconic_block@0"
            ]
        },
        {
            "x": -10,
            "y": -9,
            "z": -1,
            "elements": [
                "botania:storage@1"
            ]
        },
        {
            "x": 2,
            "y": -7,
            "z": -8,
            "elements": [
                "environmentaltech:structure_frame_5@0"
            ]
        },
        {
            "x": 16,
            "y": -15,
            "z": 0,
            "elements": [
                "contenttweaker:psogereer_rock@0"
            ]
        },
        {
            "x": 8,
            "y": -7,
            "z": -3,
            "elements": [
                "environmentaltech:structure_frame_5@0"
            ]
        },
        {
            "x": 3,
            "y": -3,
            "z": 3,
            "elements": [
                "modularmachinery:blockcasing@4"
            ]
        },
        {
            "x": -10,
            "y": -9,
            "z": 2,
            "elements": [
                "botania:storage@1"
            ]
        },
        {
            "x": -1,
            "y": -3,
            "z": 4,
            "elements": [
                "modularmachinery:blockcasing@4"
            ]
        },
        {
            "x": 0,
            "y": -11,
            "z": -12,
            "elements": [
                "contenttweaker:sub_block_holder_5@0"
            ]
        },
        {
            "x": -2,
            "y": -9,
            "z": -10,
            "elements": [
                "botania:storage@1"
            ]
        },
        {
            "x": 12,
            "y": -15,
            "z": 12,
            "elements": [
                "contenttweaker:psogereer_rock@0"
            ]
        },
        {
            "x": 5,
            "y": -9,
            "z": -9,
            "elements": [
                "botania:storage@1"
            ]
        },
        {
            "x": 2,
            "y": -3,
            "z": -4,
            "elements": [
                "modularmachinery:blockcasing@4"
            ]
        },
        {
            "x": 0,
            "y": -11,
            "z": -5,
            "elements": [
                "draconicevolution:draconic_block@0"
            ]
        },
        {
            "x": 14,
            "y": -15,
            "z": -8,
            "elements": [
                "contenttweaker:psogereer_rock@0"
            ]
        },
        {
            "x": 5,
            "y": -11,
            "z": -11,
            "elements": [
                "contenttweaker:sub_block_holder_5@0"
            ]
        },
        {
            "x": 0,
            "y": -7,
            "z": 4,
            "elements": [
                "draconicevolution:draconic_block@0"
            ]
        },
        {
            "x": -10,
            "y": -13,
            "z": -11,
            "elements": [
                "thaumcraft:metal_thaumium@0"
            ]
        },
        {
            "x": -12,
            "y": -11,
            "z": 1,
            "elements": [
                "contenttweaker:sub_block_holder_5@0"
            ]
        },
        {
            "x": 1,
            "y": -13,
            "z": -14,
            "elements": [
                "thaumcraft:metal_thaumium@0"
            ]
        },
        {
            "x": -4,
            "y": -5,
            "z": 5,
            "elements": [
                "enderio:block_alloy@8"
            ]
        },
        {
            "x": 0,
            "y": -15,
            "z": 16,
            "elements": [
                "contenttweaker:psogereer_rock@0"
            ]
        },
        {
            "x": 1,
            "y": -11,
            "z": 0,
            "elements": [
                "draconicevolution:draconic_block@0"
            ]
        },
        {
            "x": -3,
            "y": -9,
            "z": 10,
            "elements": [
                "botania:storage@1"
            ]
        },
        {
            "x": -11,
            "y": -11,
            "z": 6,
            "elements": [
                "contenttweaker:sub_block_holder_5@0"
            ]
        },
        {
            "x": -13,
            "y": -13,
            "z": 7,
            "elements": [
                "thaumcraft:metal_thaumium@0"
            ]
        },
        {
            "x": 4,
            "y": -15,
            "z": 0,
            "elements": [
                "draconicevolution:draconic_block@0"
            ]
        },
        {
            "x": 6,
            "y": -11,
            "z": 11,
            "elements": [
                "contenttweaker:sub_block_holder_5@0"
            ]
        },
        {
            "x": 3,
            "y": -15,
            "z": 16,
            "elements": [
                "contenttweaker:psogereer_rock@0"
            ]
        },
        {
            "x": -16,
            "y": -15,
            "z": 2,
            "elements": [
                "contenttweaker:psogereer_rock@0"
            ]
        },
        {
            "x": -10,
            "y": -13,
            "z": -10,
            "elements": [
                "thaumcraft:metal_thaumium@0"
            ]
        },
        {
            "x": 0,
            "y": -7,
            "z": 3,
            "elements": [
                "draconicevolution:draconic_block@0"
            ]
        },
        {
            "x": -9,
            "y": -11,
            "z": 8,
            "elements": [
                "contenttweaker:sub_block_holder_5@0"
            ]
        },
        {
            "x": -4,
            "y": -7,
            "z": -8,
            "elements": [
                "environmentaltech:structure_frame_5@0"
            ]
        },
        {
            "x": -2,
            "y": -7,
            "z": 0,
            "elements": [
                "draconicevolution:draconic_block@0"
            ]
        },
        {
            "x": -6,
            "y": -9,
            "z": 8,
            "elements": [
                "botania:storage@1"
            ]
        },
        {
            "x": 12,
            "y": -15,
            "z": 11,
            "elements": [
                "contenttweaker:psogereer_rock@0"
            ]
        },
        {
            "x": -12,
            "y": -13,
            "z": -8,
            "elements": [
                "thaumcraft:metal_thaumium@0"
            ]
        },
        {
            "x": 10,
            "y": -15,
            "z": 0,
            "elements": [
                "draconicevolution:draconic_block@0"
            ]
        },
        {
            "x": 0,
            "y": -11,
            "z": -4,
            "elements": [
                "draconicevolution:draconic_block@0"
            ]
        },
        {
            "x": -14,
            "y": -13,
            "z": -1,
            "elements": [
                "thaumcraft:metal_thaumium@0"
            ]
        },
        {
            "x": -3,
            "y": -3,
            "z": 3,
            "elements": [
                "modularmachinery:blockcasing@4"
            ]
        },
        {
            "x": 16,
            "y": -15,
            "z": 1,
            "elements": [
                "contenttweaker:psogereer_rock@0"
            ]
        },
        {
            "x": -5,
            "y": -15,
            "z": 0,
            "elements": [
                "draconicevolution:draconic_block@0"
            ]
        },
        {
            "x": 0,
            "y": -15,
            "z": -2,
            "elements": [
                "draconicevolution:draconic_block@0"
            ]
        },
        {
            "x": 4,
            "y": -9,
            "z": -10,
            "elements": [
                "botania:storage@1"
            ]
        },
        {
            "x": -5,
            "y": -13,
            "z": -14,
            "elements": [
                "thaumcraft:metal_thaumium@0"
            ]
        },
        {
            "x": -7,
            "y": -9,
            "z": 8,
            "elements": [
                "botania:storage@1"
            ]
        },
        {
            "x": 3,
            "y": -9,
            "z": 10,
            "elements": [
                "botania:storage@1"
            ]
        },
        {
            "x": -9,
            "y": -9,
            "z": -6,
            "elements": [
                "botania:storage@1"
            ]
        },
        {
            "x": 0,
            "y": -3,
            "z": 3,
            "elements": [
                "draconicevolution:draconic_block@0"
            ]
        },
        {
            "x": 0,
            "y": -11,
            "z": 4,
            "elements": [
                "draconicevolution:draconic_block@0"
            ]
        },
        {
            "x": -1,
            "y": -7,
            "z": -8,
            "elements": [
                "environmentaltech:structure_frame_5@0"
            ]
        },
        {
            "x": 9,
            "y": -13,
            "z": 11,
            "elements": [
                "thaumcraft:metal_thaumium@0"
            ]
        },
        {
            "x": 0,
            "y": -15,
            "z": 9,
            "elements": [
                "draconicevolution:draconic_block@0"
            ]
        },
        {
            "x": -13,
            "y": -15,
            "z": -10,
            "elements": [
                "contenttweaker:psogereer_rock@0"
            ]
        },
        {
            "x": 0,
            "y": -3,
            "z": -3,
            "elements": [
                "draconicevolution:draconic_block@0"
            ]
        },
        {
            "x": -14,
            "y": -13,
            "z": -2,
            "elements": [
                "thaumcraft:metal_thaumium@0"
            ]
        },
        {
            "x": -8,
            "y": -11,
            "z": 0,
            "elements": [
                "draconicevolution:draconic_block@0"
            ]
        },
        {
            "x": 7,
            "y": -7,
            "z": -4,
            "elements": [
                "environmentaltech:structure_frame_5@0"
            ]
        },
        {
            "x": 10,
            "y": -9,
            "z": 2,
            "elements": [
                "botania:storage@1"
            ]
        },
        {
            "x": 10,
            "y": -9,
            "z": -4,
            "elements": [
                "botania:storage@1"
            ]
        },
        {
            "x": -2,
            "y": -15,
            "z": 0,
            "elements": [
                "draconicevolution:draconic_block@0"
            ]
        },
        {
            "x": -9,
            "y": -15,
            "z": 14,
            "elements": [
                "contenttweaker:psogereer_rock@0"
            ]
        },
        {
            "x": -15,
            "y": -15,
            "z": 7,
            "elements": [
                "contenttweaker:psogereer_rock@0"
            ]
        },
        {
            "x": 0,
            "y": -11,
            "z": -8,
            "elements": [
                "draconicevolution:draconic_block@0"
            ]
        },
        {
            "x": -2,
            "y": -13,
            "z": -14,
            "elements": [
                "thaumcraft:metal_thaumium@0"
            ]
        },
        {
            "x": -13,
            "y": -13,
            "z": 6,
            "elements": [
                "thaumcraft:metal_thaumium@0"
            ]
        },
        {
            "x": -8,
            "y": -7,
            "z": 0,
            "elements": [
                "environmentaltech:structure_frame_5@0"
            ]
        },
        {
            "x": -14,
            "y": -15,
            "z": -9,
            "elements": [
                "contenttweaker:psogereer_rock@0"
            ]
        },
        {
            "x": 12,
            "y": -11,
            "z": -2,
            "elements": [
                "contenttweaker:sub_block_holder_5@0"
            ]
        },
        {
            "x": 1,
            "y": -15,
            "z": 16,
            "elements": [
                "contenttweaker:psogereer_rock@0"
            ]
        },
        {
            "x": -11,
            "y": -15,
            "z": 12,
            "elements": [
                "contenttweaker:psogereer_rock@0"
            ]
        },
        {
            "x": 0,
            "y": -7,
            "z": -4,
            "elements": [
                "draconicevolution:draconic_block@0"
            ]
        },
        {
            "x": -5,
            "y": -11,
            "z": 0,
            "elements": [
                "draconicevolution:draconic_block@0"
            ]
        },
        {
            "x": -2,
            "y": -3,
            "z": -4,
            "elements": [
                "modularmachinery:blockcasing@4"
            ]
        },
        {
            "x": -8,
            "y": -9,
            "z": -7,
            "elements": [
                "botania:storage@1"
            ]
        },
        {
            "x": -4,
            "y": -11,
            "z": -12,
            "elements": [
                "contenttweaker:sub_block_holder_5@0"
            ]
        },
        {
            "x": 16,
            "y": -15,
            "z": 2,
            "elements": [
                "contenttweaker:psogereer_rock@0"
            ]
        },
        {
            "x": -12,
            "y": -15,
            "z": -11,
            "elements": [
                "contenttweaker:psogereer_rock@0"
            ]
        },
        {
            "x": -8,
            "y": -15,
            "z": -14,
            "elements": [
                "contenttweaker:psogereer_rock@0"
            ]
        },
        {
            "x": 1,
            "y": -15,
            "z": 0,
            "elements": [
                "draconicevolution:draconic_block@0"
            ]
        },
        {
            "x": -6,
            "y": -9,
            "z": 9,
            "elements": [
                "botania:storage@1"
            ]
        },
        {
            "x": 11,
            "y": -13,
            "z": 9,
            "elements": [
                "thaumcraft:metal_thaumium@0"
            ]
        },
        {
            "x": -6,
            "y": -13,
            "z": -13,
            "elements": [
                "thaumcraft:metal_thaumium@0"
            ]
        },
        {
            "x": 16,
            "y": -15,
            "z": 4,
            "elements": [
                "contenttweaker:psogereer_rock@0"
            ]
        },
        {
            "x": 8,
            "y": -11,
            "z": 9,
            "elements": [
                "contenttweaker:sub_block_holder_5@0"
            ]
        },
        {
            "x": -8,
            "y": -15,
            "z": 0,
            "elements": [
                "draconicevolution:draconic_block@0"
            ]
        },
        {
            "x": -13,
            "y": -15,
            "z": 10,
            "elements": [
                "contenttweaker:psogereer_rock@0"
            ]
        },
        {
            "x": -1,
            "y": -11,
            "z": -12,
            "elements": [
                "contenttweaker:sub_block_holder_5@0"
            ]
        },
        {
            "x": 0,
            "y": -7,
            "z": 8,
            "elements": [
                "environmentaltech:structure_frame_5@0"
            ]
        },
        {
            "x": 4,
            "y": -7,
            "z": 7,
            "elements": [
                "environmentaltech:structure_frame_5@0"
            ]
        },
        {
            "x": -4,
            "y": -3,
            "z": -2,
            "elements": [
                "modularmachinery:blockcasing@4"
            ]
        },
        {
            "x": 0,
            "y": -7,
            "z": -6,
            "elements": [
                "draconicevolution:draconic_block@0"
            ]
        },
        {
            "x": -10,
            "y": -11,
            "z": 0,
            "elements": [
                "draconicevolution:draconic_block@0"
            ]
        },
        {
            "x": 0,
            "y": -15,
            "z": -15,
            "elements": [
                "draconicevolution:draconic_block@0"
            ]
        },
        {
            "x": 12,
            "y": -11,
            "z": -4,
            "elements": [
                "contenttweaker:sub_block_holder_5@0"
            ]
        },
        {
            "x": -14,
            "y": -13,
            "z": -4,
            "elements": [
                "thaumcraft:metal_thaumium@0"
            ]
        },
        {
            "x": -16,
            "y": -15,
            "z": 4,
            "elements": [
                "contenttweaker:psogereer_rock@0"
            ]
        },
        {
            "x": -9,
            "y": -15,
            "z": 0,
            "elements": [
                "draconicevolution:draconic_block@0"
            ]
        },
        {
            "x": 12,
            "y": -11,
            "z": -3,
            "elements": [
                "contenttweaker:sub_block_holder_5@0"
            ]
        },
        {
            "x": 16,
            "y": -15,
            "z": 3,
            "elements": [
                "contenttweaker:psogereer_rock@0"
            ]
        },
        {
            "x": -3,
            "y": -7,
            "z": 8,
            "elements": [
                "environmentaltech:structure_frame_5@0"
            ]
        },
        {
            "x": -7,
            "y": -11,
            "z": -10,
            "elements": [
                "contenttweaker:sub_block_holder_5@0"
            ]
        },
        {
            "x": 8,
            "y": -13,
            "z": -12,
            "elements": [
                "thaumcraft:metal_thaumium@0"
            ]
        },
        {
            "x": 0,
            "y": -7,
            "z": -8,
            "elements": [
                "environmentaltech:structure_frame_5@0"
            ]
        },
        {
            "x": -9,
            "y": -13,
            "z": -11,
            "elements": [
                "thaumcraft:metal_thaumium@0"
            ]
        },
        {
            "x": -10,
            "y": -9,
            "z": 0,
            "elements": [
                "botania:storage@1"
            ]
        },
        {
            "x": -16,
            "y": -15,
            "z": 3,
            "elements": [
                "contenttweaker:psogereer_rock@0"
            ]
        },
        {
            "x": 6,
            "y": -9,
            "z": 8,
            "elements": [
                "botania:storage@1"
            ]
        },
        {
            "x": 7,
            "y": -7,
            "z": 4,
            "elements": [
                "environmentaltech:structure_frame_5@0"
            ]
        },
        {
            "x": -8,
            "y": -7,
            "z": 1,
            "elements": [
                "environmentaltech:structure_frame_5@0"
            ]
        },
        {
            "x": 3,
            "y": -3,
            "z": -3,
            "elements": [
                "modularmachinery:blockcasing@4"
            ]
        },
        {
            "x": -9,
            "y": -9,
            "z": -5,
            "elements": [
                "botania:storage@1"
            ]
        },
        {
            "x": -14,
            "y": -13,
            "z": -3,
            "elements": [
                "thaumcraft:metal_thaumium@0"
            ]
        },
        {
            "x": -4,
            "y": -3,
            "z": 2,
            "elements": [
                "modularmachinery:blockcasing@4"
            ]
        },
        {
            "x": -11,
            "y": -11,
            "z": 0,
            "elements": [
                "draconicevolution:draconic_block@0"
            ]
        },
        {
            "x": 15,
            "y": -15,
            "z": -7,
            "elements": [
                "contenttweaker:psogereer_rock@0"
            ]
        },
        {
            "x": 12,
            "y": -11,
            "z": 4,
            "elements": [
                "contenttweaker:sub_block_holder_5@0"
            ]
        },
        {
            "x": 12,
            "y": -13,
            "z": -8,
            "elements": [
                "thaumcraft:metal_thaumium@0"
            ]
        },
        {
            "x": 0,
            "y": -11,
            "z": -9,
            "elements": [
                "draconicevolution:draconic_block@0"
            ]
        },
        {
            "x": 0,
            "y": -5,
            "z": -6,
            "elements": [
                "enderio:block_alloy@8"
            ]
        },
        {
            "x": 0,
            "y": -15,
            "z": 1,
            "elements": [
                "draconicevolution:draconic_block@0"
            ]
        },
        {
            "x": 3,
            "y": -7,
            "z": -8,
            "elements": [
                "environmentaltech:structure_frame_5@0"
            ]
        },
        {
            "x": -16,
            "y": -15,
            "z": -4,
            "elements": [
                "contenttweaker:psogereer_rock@0"
            ]
        },
        {
            "x": -6,
            "y": -7,
            "z": -6,
            "elements": [
                "environmentaltech:structure_frame_5@0"
            ]
        },
        {
            "x": -6,
            "y": -5,
            "z": 1,
            "elements": [
                "enderio:block_alloy@8"
            ]
        },
        {
            "x": 2,
            "y": -1,
            "z": 2,
            "elements": [
                "libvulpes:advstructuremachine@0"
            ]
        },
        {
            "x": -12,
            "y": -15,
            "z": 12,
            "elements": [
                "contenttweaker:psogereer_rock@0"
            ]
        },
        {
            "x": -3,
            "y": -3,
            "z": -3,
            "elements": [
                "modularmachinery:blockcasing@4"
            ]
        },
        {
            "x": -11,
            "y": -11,
            "z": -5,
            "elements": [
                "contenttweaker:sub_block_holder_5@0"
            ]
        },
        {
            "x": 14,
            "y": -13,
            "z": -2,
            "elements": [
                "thaumcraft:metal_thaumium@0"
            ]
        },
        {
            "x": 8,
            "y": -7,
            "z": -2,
            "elements": [
                "environmentaltech:structure_frame_5@0"
            ]
        },
        {
            "x": 8,
            "y": -15,
            "z": 14,
            "elements": [
                "contenttweaker:psogereer_rock@0"
            ]
        },
        {
            "x": 11,
            "y": -15,
            "z": -12,
            "elements": [
                "contenttweaker:psogereer_rock@0"
            ]
        },
        {
            "x": -11,
            "y": -13,
            "z": 10,
            "elements": [
                "thaumcraft:metal_thaumium@0"
            ]
        },
        {
            "x": -9,
            "y": -15,
            "z": -14,
            "elements": [
                "contenttweaker:psogereer_rock@0"
            ]
        },
        {
            "x": -12,
            "y": -11,
            "z": 0,
            "elements": [
                "contenttweaker:sub_block_holder_5@0"
            ]
        },
        {
            "x": -6,
            "y": -15,
            "z": 0,
            "elements": [
                "draconicevolution:draconic_block@0"
            ]
        },
        {
            "x": 5,
            "y": -13,
            "z": 14,
            "elements": [
                "thaumcraft:metal_thaumium@0"
            ]
        },
        {
            "x": -1,
            "y": -1,
            "z": -2,
            "elements": [
                "libvulpes:advstructuremachine@0"
            ]
        },
        {
            "x": -16,
            "y": -15,
            "z": -1,
            "elements": [
                "contenttweaker:psogereer_rock@0"
            ]
        },
        {
            "x": 13,
            "y": -13,
            "z": 7,
            "elements": [
                "thaumcraft:metal_thaumium@0"
            ]
        },
        {
            "x": -11,
            "y": -15,
            "z": 0,
            "elements": [
                "draconicevolution:draconic_block@0"
            ]
        },
        {
            "x": 2,
            "y": -1,
            "z": -2,
            "elements": [
                "libvulpes:advstructuremachine@0"
            ]
        },
        {
            "x": 10,
            "y": -11,
            "z": 7,
            "elements": [
                "contenttweaker:sub_block_holder_5@0"
            ]
        },
        {
            "x": 0,
            "y": -7,
            "z": -3,
            "elements": [
                "draconicevolution:draconic_block@0"
            ]
        },
        {
            "x": 16,
            "y": -15,
            "z": -4,
            "elements": [
                "contenttweaker:psogereer_rock@0"
            ]
        },
        {
            "x": 12,
            "y": -11,
            "z": 1,
            "elements": [
                "contenttweaker:sub_block_holder_5@0"
            ]
        },
        {
            "x": 0,
            "y": -15,
            "z": -11,
            "elements": [
                "draconicevolution:draconic_block@0"
            ]
        },
        {
            "x": -5,
            "y": -5,
            "z": -4,
            "elements": [
                "enderio:block_alloy@8"
            ]
        },
        {
            "x": -3,
            "y": -15,
            "z": 16,
            "elements": [
                "contenttweaker:psogereer_rock@0"
            ]
        },
        {
            "x": 6,
            "y": -5,
            "z": -3,
            "elements": [
                "enderio:block_alloy@8"
            ]
        },
        {
            "x": 15,
            "y": -15,
            "z": -6,
            "elements": [
                "contenttweaker:psogereer_rock@0"
            ]
        },
        {
            "x": -9,
            "y": -11,
            "z": 0,
            "elements": [
                "draconicevolution:draconic_block@0"
            ]
        },
        {
            "x": 3,
            "y": -7,
            "z": 8,
            "elements": [
                "environmentaltech:structure_frame_5@0"
            ]
        },
        {
            "x": 0,
            "y": -15,
            "z": 8,
            "elements": [
                "draconicevolution:draconic_block@0"
            ]
        },
        {
            "x": 8,
            "y": -7,
            "z": 2,
            "elements": [
                "environmentaltech:structure_frame_5@0"
            ]
        },
        {
            "x": 10,
            "y": -9,
            "z": 4,
            "elements": [
                "botania:storage@1"
            ]
        },
        {
            "x": 0,
            "y": -15,
            "z": -13,
            "elements": [
                "draconicevolution:draconic_block@0"
            ]
        },
        {
            "x": 1,
            "y": -1,
            "z": -2,
            "elements": [
                "libvulpes:advstructuremachine@0"
            ]
        },
        {
            "x": 0,
            "y": -15,
            "z": -14,
            "elements": [
                "draconicevolution:draconic_block@0"
            ]
        },
        {
            "x": 14,
            "y": -15,
            "z": 9,
            "elements": [
                "contenttweaker:psogereer_rock@0"
            ]
        },
        {
            "x": -6,
            "y": -5,
            "z": -3,
            "elements": [
                "enderio:block_alloy@8"
            ]
        },
        {
            "x": 0,
            "y": -15,
            "z": -6,
            "elements": [
                "draconicevolution:draconic_block@0"
            ]
        },
        {
            "x": 5,
            "y": -9,
            "z": 9,
            "elements": [
                "botania:storage@1"
            ]
        },
        {
            "x": -8,
            "y": -7,
            "z": 4,
            "elements": [
                "environmentaltech:structure_frame_5@0"
            ]
        },
        {
            "x": 2,
            "y": -11,
            "z": -12,
            "elements": [
                "contenttweaker:sub_block_holder_5@0"
            ]
        },
        {
            "x": -2,
            "y": -1,
            "z": -1,
            "elements": [
                "libvulpes:advstructuremachine@0"
            ]
        },
        {
            "x": -4,
            "y": -7,
            "z": 8,
            "elements": [
                "environmentaltech:structure_frame_5@0"
            ]
        },
        {
            "x": 0,
            "y": -1,
            "z": 2,
            "elements": [
                "libvulpes:advstructuremachine@0"
            ]
        },
        {
            "x": 8,
            "y": -13,
            "z": 12,
            "elements": [
                "thaumcraft:metal_thaumium@0"
            ]
        },
        {
            "x": 10,
            "y": -9,
            "z": -1,
            "elements": [
                "botania:storage@1"
            ]
        },
        {
            "x": -6,
            "y": -11,
            "z": 0,
            "elements": [
                "draconicevolution:draconic_block@0"
            ]
        },
        {
            "x": 0,
            "y": -11,
            "z": -7,
            "elements": [
                "draconicevolution:draconic_block@0"
            ]
        },
        {
            "x": -4,
            "y": -15,
            "z": 0,
            "elements": [
                "draconicevolution:draconic_block@0"
            ]
        },
        {
            "x": 0,
            "y": -3,
            "z": -2,
            "elements": [
                "draconicevolution:draconic_block@0"
            ]
        },
        {
            "x": 0,
            "y": -15,
            "z": -9,
            "elements": [
                "draconicevolution:draconic_block@0"
            ]
        },
        {
            "x": -7,
            "y": -7,
            "z": -5,
            "elements": [
                "environmentaltech:structure_frame_5@0"
            ]
        },
        {
            "x": 6,
            "y": -13,
            "z": -13,
            "elements": [
                "thaumcraft:metal_thaumium@0"
            ]
        },
        {
            "x": -13,
            "y": -15,
            "z": 0,
            "elements": [
                "draconicevolution:draconic_block@0"
            ]
        },
        {
            "x": -8,
            "y": -7,
            "z": 3,
            "elements": [
                "environmentaltech:structure_frame_5@0"
            ]
        },
        {
            "x": -12,
            "y": -15,
            "z": -12,
            "elements": [
                "contenttweaker:psogereer_rock@0"
            ]
        },
        {
            "x": 0,
            "y": -13,
            "z": -14,
            "elements": [
                "thaumcraft:metal_thaumium@0"
            ]
        },
        {
            "x": 9,
            "y": -15,
            "z": -14,
            "elements": [
                "contenttweaker:psogereer_rock@0"
            ]
        },
        {
            "x": 4,
            "y": -7,
            "z": -8,
            "elements": [
                "environmentaltech:structure_frame_5@0"
            ]
        },
        {
            "x": -7,
            "y": -13,
            "z": 13,
            "elements": [
                "thaumcraft:metal_thaumium@0"
            ]
        },
        {
            "x": -4,
            "y": -13,
            "z": 14,
            "elements": [
                "thaumcraft:metal_thaumium@0"
            ]
        },
        {
            "x": -14,
            "y": -13,
            "z": 1,
            "elements": [
                "thaumcraft:metal_thaumium@0"
            ]
        },
        {
            "x": 10,
            "y": -11,
            "z": -8,
            "elements": [
                "contenttweaker:sub_block_holder_5@0"
            ]
        },
        {
            "x": -5,
            "y": -11,
            "z": -11,
            "elements": [
                "contenttweaker:sub_block_holder_5@0"
            ]
        },
        {
            "x": 1,
            "y": -7,
            "z": 8,
            "elements": [
                "environmentaltech:structure_frame_5@0"
            ]
        },
        {
            "x": -1,
            "y": -1,
            "z": 2,
            "elements": [
                "libvulpes:advstructuremachine@0"
            ]
        },
        {
            "x": -7,
            "y": -11,
            "z": 0,
            "elements": [
                "draconicevolution:draconic_block@0"
            ]
        },
        {
            "x": 0,
            "y": -3,
            "z": 2,
            "elements": [
                "draconicevolution:draconic_block@0"
            ]
        },
        {
            "x": -4,
            "y": -9,
            "z": -10,
            "elements": [
                "botania:storage@1"
            ]
        },
        {
            "x": 0,
            "y": -11,
            "z": -3,
            "elements": [
                "draconicevolution:draconic_block@0"
            ]
        },
        {
            "x": 0,
            "y": -1,
            "z": -2,
            "elements": [
                "libvulpes:advstructuremachine@0"
            ]
        },
        {
            "x": 13,
            "y": -13,
            "z": 6,
            "elements": [
                "thaumcraft:metal_thaumium@0"
            ]
        },
        {
            "x": 5,
            "y": -15,
            "z": -16,
            "elements": [
                "contenttweaker:psogereer_rock@0"
            ]
        },
        {
            "x": -12,
            "y": -15,
            "z": 11,
            "elements": [
                "contenttweaker:psogereer_rock@0"
            ]
        },
        {
            "x": 16,
            "y": -15,
            "z": -1,
            "elements": [
                "contenttweaker:psogereer_rock@0"
            ]
        },
        {
            "x": -8,
            "y": -7,
            "z": -1,
            "elements": [
                "environmentaltech:structure_frame_5@0"
            ]
        },
        {
            "x": -8,
            "y": -11,
            "z": -10,
            "elements": [
                "contenttweaker:sub_block_holder_5@0"
            ]
        },
        {
            "x": -5,
            "y": -5,
            "z": 4,
            "elements": [
                "enderio:block_alloy@8"
            ]
        },
        {
            "x": -14,
            "y": -13,
            "z": -5,
            "elements": [
                "thaumcraft:metal_thaumium@0"
            ]
        },
        {
            "x": 0,
            "y": -7,
            "z": -7,
            "elements": [
                "draconicevolution:draconic_block@0"
            ]
        },
        {
            "x": -16,
            "y": -15,
            "z": 5,
            "elements": [
                "contenttweaker:psogereer_rock@0"
            ]
        },
        {
            "x": 0,
            "y": -11,
            "z": 8,
            "elements": [
                "draconicevolution:draconic_block@0"
            ]
        },
        {
            "x": -10,
            "y": -15,
            "z": 0,
            "elements": [
                "draconicevolution:draconic_block@0"
            ]
        },
        {
            "x": 3,
            "y": -13,
            "z": -14,
            "elements": [
                "thaumcraft:metal_thaumium@0"
            ]
        },
        {
            "x": -6,
            "y": -11,
            "z": -11,
            "elements": [
                "contenttweaker:sub_block_holder_5@0"
            ]
        },
        {
            "x": -2,
            "y": -7,
            "z": 8,
            "elements": [
                "environmentaltech:structure_frame_5@0"
            ]
        },
        {
            "x": 9,
            "y": -11,
            "z": -8,
            "elements": [
                "contenttweaker:sub_block_holder_5@0"
            ]
        },
        {
            "x": 6,
            "y": -9,
            "z": -8,
            "elements": [
                "botania:storage@1"
            ]
        },
        {
            "x": -2,
            "y": -1,
            "z": 2,
            "elements": [
                "libvulpes:advstructuremachine@0"
            ]
        },
        {
            "x": 0,
            "y": -15,
            "z": -3,
            "elements": [
                "draconicevolution:draconic_block@0"
            ]
        },
        {
            "x": 0,
            "y": -11,
            "z": -6,
            "elements": [
                "draconicevolution:draconic_block@0"
            ]
        },
        {
            "x": -3,
            "y": -5,
            "z": -6,
            "elements": [
                "enderio:block_alloy@8"
            ]
        },
        {
            "x": 11,
            "y": -11,
            "z": 6,
            "elements": [
                "contenttweaker:sub_block_holder_5@0"
            ]
        },
        {
            "x": 11,
            "y": -15,
            "z": 12,
            "elements": [
                "contenttweaker:psogereer_rock@0"
            ]
        },
        {
            "x": -8,
            "y": -7,
            "z": -4,
            "elements": [
                "environmentaltech:structure_frame_5@0"
            ]
        },
        {
            "x": -7,
            "y": -15,
            "z": 0,
            "elements": [
                "draconicevolution:draconic_block@0"
            ]
        },
        {
            "x": 8,
            "y": -9,
            "z": 6,
            "elements": [
                "botania:storage@1"
            ]
        },
        {
            "x": 16,
            "y": -15,
            "z": 5,
            "elements": [
                "contenttweaker:psogereer_rock@0"
            ]
        },
        {
            "x": -6,
            "y": -15,
            "z": -15,
            "elements": [
                "contenttweaker:psogereer_rock@0"
            ]
        },
        {
            "x": 7,
            "y": -9,
            "z": -8,
            "elements": [
                "botania:storage@1"
            ]
        },
        {
            "x": 1,
            "y": -1,
            "z": 2,
            "elements": [
                "libvulpes:advstructuremachine@0"
            ]
        },
        {
            "x": 4,
            "y": -3,
            "z": -1,
            "elements": [
                "modularmachinery:blockcasing@4"
            ]
        },
        {
            "x": -1,
            "y": -7,
            "z": 8,
            "elements": [
                "environmentaltech:structure_frame_5@0"
            ]
        },
        {
            "x": 10,
            "y": -9,
            "z": 3,
            "elements": [
                "botania:storage@1"
            ]
        },
        {
            "x": 6,
            "y": -5,
            "z": 1,
            "elements": [
                "enderio:block_alloy@8"
            ]
        },
        {
            "x": -5,
            "y": -7,
            "z": 7,
            "elements": [
                "environmentaltech:structure_frame_5@0"
            ]
        },
        {
            "x": -9,
            "y": -9,
            "z": 5,
            "elements": [
                "botania:storage@1"
            ]
        },
        {
            "x": -9,
            "y": -11,
            "z": -9,
            "elements": [
                "contenttweaker:sub_block_holder_5@0"
            ]
        },
        {
            "x": -11,
            "y": -13,
            "z": -10,
            "elements": [
                "thaumcraft:metal_thaumium@0"
            ]
        },
        {
            "x": 14,
            "y": -13,
            "z": 0,
            "elements": [
                "thaumcraft:metal_thaumium@0"
            ]
        },
        {
            "x": -2,
            "y": -1,
            "z": -2,
            "elements": [
                "libvulpes:advstructuremachine@0"
            ]
        },
        {
            "x": -8,
            "y": -9,
            "z": 7,
            "elements": [
                "botania:storage@1"
            ]
        },
        {
            "x": 2,
            "y": -5,
            "z": -6,
            "elements": [
                "enderio:block_alloy@8"
            ]
        },
        {
            "x": 2,
            "y": -1,
            "z": -1,
            "elements": [
                "libvulpes:advstructuremachine@0"
            ]
        },
        {
            "x": 13,
            "y": -13,
            "z": -7,
            "elements": [
                "thaumcraft:metal_thaumium@0"
            ]
        },
        {
            "x": -6,
            "y": -5,
            "z": 0,
            "elements": [
                "enderio:block_alloy@8"
            ]
        },
        {
            "x": -6,
            "y": -13,
            "z": 13,
            "elements": [
                "thaumcraft:metal_thaumium@0"
            ]
        },
        {
            "x": 11,
            "y": -13,
            "z": 10,
            "elements": [
                "thaumcraft:metal_thaumium@0"
            ]
        },
        {
            "x": -12,
            "y": -11,
            "z": -3,
            "elements": [
                "contenttweaker:sub_block_holder_5@0"
            ]
        },
        {
            "x": 8,
            "y": -11,
            "z": 10,
            "elements": [
                "contenttweaker:sub_block_holder_5@0"
            ]
        },
        {
            "x": 3,
            "y": -11,
            "z": 12,
            "elements": [
                "contenttweaker:sub_block_holder_5@0"
            ]
        },
        {
            "x": 6,
            "y": -5,
            "z": 2,
            "elements": [
                "enderio:block_alloy@8"
            ]
        },
        {
            "x": -15,
            "y": -15,
            "z": -6,
            "elements": [
                "contenttweaker:psogereer_rock@0"
            ]
        },
        {
            "x": -1,
            "y": -13,
            "z": 14,
            "elements": [
                "thaumcraft:metal_thaumium@0"
            ]
        },
        {
            "x": -12,
            "y": -11,
            "z": -4,
            "elements": [
                "contenttweaker:sub_block_holder_5@0"
            ]
        },
        {
            "x": 0,
            "y": -15,
            "z": 0,
            "elements": [
                "modularmachinery:blockenergyinputhatch"
            ]
        },
        {
            "x": -14,
            "y": -13,
            "z": 4,
            "elements": [
                "thaumcraft:metal_thaumium@0"
            ]
        },
        {
            "x": -14,
            "y": -13,
            "z": 3,
            "elements": [
                "thaumcraft:metal_thaumium@0"
            ]
        },
        {
            "x": -4,
            "y": -7,
            "z": 7,
            "elements": [
                "environmentaltech:structure_frame_5@0"
            ]
        },
        {
            "x": 4,
            "y": -3,
            "z": -2,
            "elements": [
                "modularmachinery:blockcasing@4"
            ]
        },
        {
            "x": -7,
            "y": -11,
            "z": 10,
            "elements": [
                "contenttweaker:sub_block_holder_5@0"
            ]
        },
        {
            "x": 10,
            "y": -13,
            "z": 10,
            "elements": [
                "thaumcraft:metal_thaumium@0"
            ]
        },
        {
            "x": 0,
            "y": -15,
            "z": 13,
            "elements": [
                "draconicevolution:draconic_block@0"
            ]
        },
        {
            "x": -6,
            "y": -7,
            "z": 0,
            "elements": [
                "draconicevolution:draconic_block@0"
            ]
        },
        {
            "x": 9,
            "y": -9,
            "z": 5,
            "elements": [
                "botania:storage@1"
            ]
        },
        {
            "x": 0,
            "y": -7,
            "z": 1,
            "elements": [
                "draconicevolution:draconic_block@0"
            ]
        },
        {
            "x": 14,
            "y": -15,
            "z": 0,
            "elements": [
                "draconicevolution:draconic_block@0"
            ]
        },
        {
            "x": -3,
            "y": -11,
            "z": 0,
            "elements": [
                "draconicevolution:draconic_block@0"
            ]
        },
        {
            "x": 0,
            "y": -9,
            "z": -10,
            "elements": [
                "botania:storage@1"
            ]
        },
        {
            "x": 0,
            "y": -11,
            "z": 2,
            "elements": [
                "draconicevolution:draconic_block@0"
            ]
        },
        {
            "x": 5,
            "y": -7,
            "z": 7,
            "elements": [
                "environmentaltech:structure_frame_5@0"
            ]
        },
        {
            "x": 0,
            "y": -13,
            "z": 14,
            "elements": [
                "thaumcraft:metal_thaumium@0"
            ]
        },
        {
            "x": 16,
            "y": -15,
            "z": -5,
            "elements": [
                "contenttweaker:psogereer_rock@0"
            ]
        },
        {
            "x": 8,
            "y": -9,
            "z": -6,
            "elements": [
                "botania:storage@1"
            ]
        },
        {
            "x": -4,
            "y": -11,
            "z": 12,
            "elements": [
                "contenttweaker:sub_block_holder_5@0"
            ]
        },
        {
            "x": 2,
            "y": -1,
            "z": 1,
            "elements": [
                "libvulpes:advstructuremachine@0"
            ]
        },
        {
            "x": 11,
            "y": -11,
            "z": -6,
            "elements": [
                "contenttweaker:sub_block_holder_5@0"
            ]
        },
        {
            "x": 0,
            "y": -7,
            "z": -1,
            "elements": [
                "draconicevolution:draconic_block@0"
            ]
        },
        {
            "x": -1,
            "y": -15,
            "z": 0,
            "elements": [
                "draconicevolution:draconic_block@0"
            ]
        },
        {
            "x": -10,
            "y": -13,
            "z": 11,
            "elements": [
                "thaumcraft:metal_thaumium@0"
            ]
        },
        {
            "x": 0,
            "y": -7,
            "z": 2,
            "elements": [
                "draconicevolution:draconic_block@0"
            ]
        },
        {
            "x": 10,
            "y": -11,
            "z": -7,
            "elements": [
                "contenttweaker:sub_block_holder_5@0"
            ]
        },
        {
            "x": -8,
            "y": -11,
            "z": -9,
            "elements": [
                "contenttweaker:sub_block_holder_5@0"
            ]
        },
        {
            "x": -4,
            "y": -15,
            "z": -16,
            "elements": [
                "contenttweaker:psogereer_rock@0"
            ]
        },
        {
            "x": 4,
            "y": -7,
            "z": -7,
            "elements": [
                "environmentaltech:structure_frame_5@0"
            ]
        },
        {
            "x": 0,
            "y": -15,
            "z": 14,
            "elements": [
                "draconicevolution:draconic_block@0"
            ]
        },
        {
            "x": -7,
            "y": -7,
            "z": 0,
            "elements": [
                "draconicevolution:draconic_block@0"
            ]
        },
        {
            "x": -1,
            "y": -11,
            "z": 0,
            "elements": [
                "draconicevolution:draconic_block@0"
            ]
        },
        {
            "x": -10,
            "y": -9,
            "z": 3,
            "elements": [
                "botania:storage@1"
            ]
        },
        {
            "x": -4,
            "y": -11,
            "z": 0,
            "elements": [
                "draconicevolution:draconic_block@0"
            ]
        },
        {
            "x": 2,
            "y": -15,
            "z": 0,
            "elements": [
                "draconicevolution:draconic_block@0"
            ]
        },
        {
            "x": -3,
            "y": -13,
            "z": 14,
            "elements": [
                "thaumcraft:metal_thaumium@0"
            ]
        },
        {
            "x": 0,
            "y": -3,
            "z": 1,
            "elements": [
                "draconicevolution:draconic_block@0"
            ]
        },
        {
            "x": -16,
            "y": -15,
            "z": -5,
            "elements": [
                "contenttweaker:psogereer_rock@0"
            ]
        },
        {
            "x": 6,
            "y": -11,
            "z": -11,
            "elements": [
                "contenttweaker:sub_block_holder_5@0"
            ]
        },
        {
            "x": -6,
            "y": -15,
            "z": 15,
            "elements": [
                "contenttweaker:psogereer_rock@0"
            ]
        },
        {
            "x": 2,
            "y": -5,
            "z": 6,
            "elements": [
                "enderio:block_alloy@8"
            ]
        },
        {
            "x": -6,
            "y": -9,
            "z": -9,
            "elements": [
                "botania:storage@1"
            ]
        },
        {
            "x": -4,
            "y": -7,
            "z": 0,
            "elements": [
                "draconicevolution:draconic_block@0"
            ]
        },
        {
            "x": -1,
            "y": -5,
            "z": -6,
            "elements": [
                "enderio:block_alloy@8"
            ]
        },
        {
            "x": 13,
            "y": -15,
            "z": 10,
            "elements": [
                "contenttweaker:psogereer_rock@0"
            ]
        },
        {
            "x": 0,
            "y": -3,
            "z": -1,
            "elements": [
                "draconicevolution:draconic_block@0"
            ]
        },
        {
            "x": 7,
            "y": -11,
            "z": 10,
            "elements": [
                "contenttweaker:sub_block_holder_5@0"
            ]
        },
        {
            "x": 3,
            "y": -11,
            "z": -12,
            "elements": [
                "contenttweaker:sub_block_holder_5@0"
            ]
        },
        {
            "x": 2,
            "y": -13,
            "z": 14,
            "elements": [
                "thaumcraft:metal_thaumium@0"
            ]
        },
        {
            "x": -10,
            "y": -9,
            "z": -4,
            "elements": [
                "botania:storage@1"
            ]
        },
        {
            "x": -3,
            "y": -15,
            "z": 0,
            "elements": [
                "draconicevolution:draconic_block@0"
            ]
        },
        {
            "x": -12,
            "y": -11,
            "z": 4,
            "elements": [
                "contenttweaker:sub_block_holder_5@0"
            ]
        },
        {
            "x": 3,
            "y": -15,
            "z": -16,
            "elements": [
                "contenttweaker:psogereer_rock@0"
            ]
        },
        {
            "x": -1,
            "y": -7,
            "z": 0,
            "elements": [
                "draconicevolution:draconic_block@0"
            ]
        },
        {
            "x": 10,
            "y": -9,
            "z": 1,
            "elements": [
                "botania:storage@1"
            ]
        },
        {
            "x": -8,
            "y": -7,
            "z": -3,
            "elements": [
                "environmentaltech:structure_frame_5@0"
            ]
        },
        {
            "x": -12,
            "y": -15,
            "z": 0,
            "elements": [
                "draconicevolution:draconic_block@0"
            ]
        },
        {
            "x": 0,
            "y": -15,
            "z": -10,
            "elements": [
                "draconicevolution:draconic_block@0"
            ]
        },
        {
            "x": 1,
            "y": -5,
            "z": 6,
            "elements": [
                "enderio:block_alloy@8"
            ]
        },
        {
            "x": -5,
            "y": -13,
            "z": 14,
            "elements": [
                "thaumcraft:metal_thaumium@0"
            ]
        },
        {
            "x": 11,
            "y": -15,
            "z": 0,
            "elements": [
                "draconicevolution:draconic_block@0"
            ]
        },
        {
            "x": 8,
            "y": -15,
            "z": -14,
            "elements": [
                "contenttweaker:psogereer_rock@0"
            ]
        },
        {
            "x": 1,
            "y": -7,
            "z": -8,
            "elements": [
                "environmentaltech:structure_frame_5@0"
            ]
        },
        {
            "x": -5,
            "y": -11,
            "z": 11,
            "elements": [
                "contenttweaker:sub_block_holder_5@0"
            ]
        },
        {
            "x": 10,
            "y": -11,
            "z": 8,
            "elements": [
                "contenttweaker:sub_block_holder_5@0"
            ]
        },
        {
            "x": -16,
            "y": -15,
            "z": -2,
            "elements": [
                "contenttweaker:psogereer_rock@0"
            ]
        },
        {
            "x": 7,
            "y": -9,
            "z": 8,
            "elements": [
                "botania:storage@1"
            ]
        },
        {
            "x": 3,
            "y": -9,
            "z": -10,
            "elements": [
                "botania:storage@1"
            ]
        },
        {
            "x": 0,
            "y": -7,
            "z": 7,
            "elements": [
                "draconicevolution:draconic_block@0"
            ]
        },
        {
            "x": -11,
            "y": -13,
            "z": -9,
            "elements": [
                "thaumcraft:metal_thaumium@0"
            ]
        },
        {
            "x": 0,
            "y": -15,
            "z": 15,
            "elements": [
                "draconicevolution:draconic_block@0"
            ]
        },
        {
            "x": 0,
            "y": -11,
            "z": -11,
            "elements": [
                "draconicevolution:draconic_block@0"
            ]
        },
        {
            "x": 4,
            "y": -7,
            "z": 8,
            "elements": [
                "environmentaltech:structure_frame_5@0"
            ]
        },
        {
            "x": 9,
            "y": -9,
            "z": -6,
            "elements": [
                "botania:storage@1"
            ]
        },
        {
            "x": -1,
            "y": -11,
            "z": 12,
            "elements": [
                "contenttweaker:sub_block_holder_5@0"
            ]
        },
        {
            "x": 2,
            "y": -15,
            "z": -16,
            "elements": [
                "contenttweaker:psogereer_rock@0"
            ]
        },
        {
            "x": -14,
            "y": -15,
            "z": -8,
            "elements": [
                "contenttweaker:psogereer_rock@0"
            ]
        },
        {
            "x": -6,
            "y": -5,
            "z": 2,
            "elements": [
                "enderio:block_alloy@8"
            ]
        },
        {
            "x": 16,
            "y": -15,
            "z": -2,
            "elements": [
                "contenttweaker:psogereer_rock@0"
            ]
        },
        {
            "x": 1,
            "y": -5,
            "z": -6,
            "elements": [
                "enderio:block_alloy@8"
            ]
        },
        {
            "x": 8,
            "y": -11,
            "z": 0,
            "elements": [
                "draconicevolution:draconic_block@0"
            ]
        },
        {
            "x": -3,
            "y": -15,
            "z": -16,
            "elements": [
                "contenttweaker:psogereer_rock@0"
            ]
        },
        {
            "x": -4,
            "y": -9,
            "z": 10,
            "elements": [
                "botania:storage@1"
            ]
        },
        {
            "x": 7,
            "y": -7,
            "z": -5,
            "elements": [
                "environmentaltech:structure_frame_5@0"
            ]
        },
        {
            "x": 12,
            "y": -15,
            "z": -12,
            "elements": [
                "contenttweaker:psogereer_rock@0"
            ]
        },
        {
            "x": -2,
            "y": -1,
            "z": 1,
            "elements": [
                "libvulpes:advstructuremachine@0"
            ]
        },
        {
            "x": 4,
            "y": -13,
            "z": 14,
            "elements": [
                "thaumcraft:metal_thaumium@0"
            ]
        },
        {
            "x": -10,
            "y": -13,
            "z": 10,
            "elements": [
                "thaumcraft:metal_thaumium@0"
            ]
        },
        {
            "x": 0,
            "y": -11,
            "z": 12,
            "elements": [
                "contenttweaker:sub_block_holder_5@0"
            ]
        },
        {
            "x": -4,
            "y": -3,
            "z": 0,
            "elements": [
                "modularmachinery:blockcasing@4"
            ]
        },
        {
            "x": 0,
            "y": -15,
            "z": 12,
            "elements": [
                "draconicevolution:draconic_block@0"
            ]
        },
        {
            "x": 12,
            "y": -11,
            "z": 2,
            "elements": [
                "contenttweaker:sub_block_holder_5@0"
            ]
        },
        {
            "x": 11,
            "y": -11,
            "z": 0,
            "elements": [
                "draconicevolution:draconic_block@0"
            ]
        },
        {
            "x": -1,
            "y": -5,
            "z": 6,
            "elements": [
                "enderio:block_alloy@8"
            ]
        },
        {
            "x": 0,
            "y": -7,
            "z": 6,
            "elements": [
                "draconicevolution:draconic_block@0"
            ]
        },
        {
            "x": 6,
            "y": -5,
            "z": -1,
            "elements": [
                "enderio:block_alloy@8"
            ]
        },
        {
            "x": -7,
            "y": -15,
            "z": -15,
            "elements": [
                "contenttweaker:psogereer_rock@0"
            ]
        },
